![[Pasted image 20250215103932.png]]

Usage of error boundary
![[Pasted image 20250215103946.png]]



Error boundary using functional component

```jsx
import React, { useState, useEffect } from "react";

const ErrorBoundary = ({ children }) => {
  const [hasError, setHasError] = useState(false);

  useEffect(() => {
    const errorHandler = (error, errorInfo) => {
      console.error("Caught error:", error, errorInfo);
      setHasError(true);
    };

    window.addEventListener("error", errorHandler);
    return () => {
      window.removeEventListener("error", errorHandler);
    };
  }, []);

  if (hasError) {
    return <h2>Something went wrong.</h2>;
  }

  return children;
};

// Example Component that throws an error
const BuggyComponent = () => {
  throw new Error("Oops! Something went wrong.");
  return <div>This will never render</div>;
};

// Usage
export default function App() {
  return (
    <ErrorBoundary>
      <BuggyComponent />
    </ErrorBoundary>
  );
}

```


```jsx
import React, { useState } from "react";
import { ErrorBoundary } from "react-error-boundary";

// Fallback UI Component
const ErrorFallback = ({ error, resetErrorBoundary }) => (
  <div>
    <h2>Something went wrong!</h2>
    <p>{error.message}</p>
    <button onClick={resetErrorBoundary}>Try Again</button>
  </div>
);

// Component that throws an error randomly
const BuggyComponent = () => {
  const [count, setCount] = useState(0);

  if (count > 2) {
    throw new Error("Counter exceeded safe limit!");
  }

  return <button onClick={() => setCount((prev) => prev + 1)}>Click {count}</button>;
};

// App Component
export default function App() {
  return (
    <ErrorBoundary FallbackComponent={ErrorFallback} onReset={() => console.log("Resetting error boundary")}>
      <BuggyComponent />
    </ErrorBoundary>
  );
}

```



### **Understanding `resetErrorBoundary` in `react-error-boundary`**

`resetErrorBoundary` is a function provided by the `react-error-boundary` package that allows you to **reset the error state** and retry rendering the component after an error occurs.

### **How to Define `resetErrorBoundary`**

- It is automatically provided to the `FallbackComponent` via props.
- Calling `resetErrorBoundary()` **resets the error state** and attempts to re-render the component.

---

## **âœ… Example with `resetErrorBoundary`**

```jsx
import React, { useState } from "react";
import { ErrorBoundary } from "react-error-boundary";

// Fallback UI Component
const ErrorFallback = ({ error, resetErrorBoundary }) => (
  <div>
    <h2>Something went wrong!</h2>
    <p>{error.message}</p>
    <button onClick={resetErrorBoundary}>Try Again</button>
  </div>
);

// Component that throws an error randomly
const BuggyComponent = () => {
  const [count, setCount] = useState(0);

  if (count > 2) {
    throw new Error("Counter exceeded safe limit!");
  }

  return <button onClick={() => setCount((prev) => prev + 1)}>Click {count}</button>;
};

// App Component
export default function App() {
  return (
    <ErrorBoundary FallbackComponent={ErrorFallback} onReset={() => console.log("Resetting error boundary")}>
      <BuggyComponent />
    </ErrorBoundary>
  );
}
```

### **ðŸ”¹ How It Works**

1. The **BuggyComponent** throws an error if the count exceeds `2`.
2. When an error occurs, **ErrorBoundary** catches it and renders **ErrorFallback**.
3. The **"Try Again"** button calls `resetErrorBoundary()`, which **resets the error state** and re-renders `BuggyComponent`.
4. The optional `onReset` callback can be used for additional state resets or logging.

---

## **âœ… Handling Errors in Async Functions (e.g., API Calls)**

By default, **React error boundaries do not catch errors inside async functions**. However, we can catch them manually and store the error in state.

### **Example: Handling Errors in an Async API Call**

```jsx
import React, { useState } from "react";
import { ErrorBoundary } from "react-error-boundary";

// Fallback UI Component
const ErrorFallback = ({ error, resetErrorBoundary }) => (
  <div>
    <h2>Something went wrong!</h2>
    <p>{error.message}</p>
    <button onClick={resetErrorBoundary}>Try Again</button>
  </div>
);

// Component that fetches data and may throw an error
const FetchDataComponent = () => {
  const [data, setData] = useState(null);
  const [error, setError] = useState(null);

  const fetchData = async () => {
    try {
      setError(null); // Reset previous errors
      const response = await fetch("https://jsonplaceholder.typicode.com/posts/1");
      if (!response.ok) {
        throw new Error("Failed to fetch data!");
      }
      const result = await response.json();
      setData(result);
    } catch (err) {
      setError(err);
    }
  };

  if (error) throw error; // Let ErrorBoundary handle this

  return (
    <div>
      <button onClick={fetchData}>Fetch Data</button>
      {data && <pre>{JSON.stringify(data, null, 2)}</pre>}
    </div>
  );
};

// App Component
export default function App() {
  return (
    <ErrorBoundary FallbackComponent={ErrorFallback} onReset={() => console.log("Retrying...")}>
      <FetchDataComponent />
    </ErrorBoundary>
  );
}
```

### **ðŸ”¹ How This Works**

1. The **`FetchDataComponent`** makes an API call when the "Fetch Data" button is clicked.
2. If an error occurs (e.g., network failure, invalid URL), it updates the `error` state.
3. When `error` is set, the component **throws** the error to be caught by `ErrorBoundary`.
4. The **ErrorBoundary** renders the `ErrorFallback` component.
5. Clicking **"Try Again"** calls `resetErrorBoundary()`, **resetting the error state and retrying**.

---

## **ðŸ”‘ Key Takeaways**

âœ… **`resetErrorBoundary()` resets the error state**, allowing components to retry rendering.  
âœ… **Use error boundaries for rendering errors**, but manually handle async errors in state.  
âœ… **To catch async errors, store them in state and throw them inside the component.**  
âœ… **Use `onReset` callback** for custom logic when retrying.

Would you like a more advanced example with retries and exponential backoff? ðŸš€